<?xml version="1.0"?>
<robot xmlns:xacro="http://www.ros.org/wiki/xacro" name="my_robot">
  

  <material name="white">
    <color rgba="1 1 1 1"/>
  </material>

  <material name="orange">
    <color rgba="1 0.3 0.1 1"/>
  </material>
  
  <material name="blue">
    <color rgba="0.2 0.2 1 1"/>
  </material>
  
  <material name="black">
    <color rgba="0 0 0 1"/>
  </material>

  <!-- <link name="base_footprint">
  </link>

  <joint name="base_link_joint" type="fixed">
    <origin xyz="0.0 0.0 0.0" rpy="0.0 0.0 0.0"/>
    <parent link="base_footprint"/>
    <child link="base_link"/>
  </joint> -->



  <link name="base_link">
    <inertial>
      <origin xyz="0.012692 0.0050409 -0.025738" rpy="-0.05 1 -0.05" />
      <mass value="0.8044" />
      <inertia
        ixx="0.0026664"
        ixy="1.82E-05"
        ixz="2.9353E-07"
        iyy="0.0015515"
        iyz="6.5283E-11"
        izz="0.0041284" />
    </inertial>
    
    <visual>
      <origin xyz="0 0 0" rpy="0 0 0" />
      <geometry>
        <mesh filename="package://my_robot/meshes/base_link.STL" scale="1.0 1.0 1.0"/>
      </geometry>
      <material name="white"/>
    </visual>

    <collision>
      <origin xyz="0 0 0" rpy="0 0 0" />
      <geometry>
        <mesh filename="package://my_robot/meshes/base_link.STL" scale="1.0 1.0 1.0"/>
      </geometry>
    </collision>
  </link>

  <link name="right_wheel">
    <inertial>
        <origin xyz="-1.1077E-07 0.0035 -8.1377E-05" rpy="1.57 0 0" />
        <mass value="0.10364" />
        <inertia ixx="8.7625E-05" ixy="1.349E-18" ixz="-1.8576E-20" iyy="0.00016817" iyz="-3.0937E-19" izz="8.7625E-05" />
    </inertial>
    <visual>
        <origin xyz="0 0 0" rpy="1.57 0 0" />
        <geometry>
            <mesh filename="package://my_robot/meshes/right_wheel.STL" />
        </geometry>
        <material name="">
            <color rgba="0.79608 0.82353 0.93725 1" />
        </material>
    </visual>
    <collision>
        <origin xyz="0 0 0" rpy="1.57 0 0" />
        <geometry>
            <mesh filename="package://my_robot/meshes/right_wheel.STL" />
        </geometry>
    </collision>
</link>

<joint name="right_wheel_joint" type="continuous">
    <origin xyz="-0.016418 -0.18164 -0.079762" rpy="1.57 0 0" />
    <parent link="base_link" />
    <child link="right_wheel" />
    <axis xyz="0 0 -1" /> <!-- Aligned with the y-axis -->
    <!-- <limit effort="10" velocity="10" />
    <dynamics damping="0.1" friction="0.1" /> -->
</joint>


 <link name="left_wheel">
    <inertial>
        <origin xyz="-1.534E-06 -0.0035 -8.1363E-05" rpy="1.57 0 0" />
        <mass value="0.10364" />
        <inertia ixx="8.7625E-05" ixy="1.3327E-18" ixz="2.4026E-21" iyy="0.00016817" iyz="-2.6053E-19" izz="8.7625E-05" />
    </inertial>
    <visual>
        <origin xyz="0 0 0" rpy="1.57 0 0" />
        <geometry>
            <mesh filename="package://my_robot/meshes/left_wheel.STL" />
        </geometry>
        <material name="">
            <color rgba="0.79608 0.82353 0.93725 1" />
        </material>
    </visual>
    <collision>
        <origin xyz="0 0 0" rpy="1.57 0 0" />
        <geometry>
            <mesh filename="package://my_robot/meshes/left_wheel.STL" />
        </geometry>
    </collision>
</link>

<joint name="left_wheel_joint" type="continuous">
    <origin xyz="-0.015294 0.18886 -0.079763" rpy="-1.57 0 0" />
    <parent link="base_link" />
    <child link="left_wheel" />
    <axis xyz="0 0 1" /> <!-- Aligned with the y-axis -->
    <!-- <limit effort="10" velocity="10" />
    <dynamics damping="0.1" friction="0.1" /> -->
</joint>

  <gazebo reference = "left_wheel">
    <material>Gazebo/Black</material>
  </gazebo>

  <link name="castor_wheels">
    <inertial>
      <origin xyz="5.5511E-17 7.6762E-16 4.1633E-17" rpy="0 0 0" />
      <mass value="0.14848" />
      <inertia
        ixx="9.1441E-05"
        ixy="1.239E-18"
        ixz="3.9667E-21"
        iyy="0.00018051"
        iyz="-1.6989E-19"
        izz="9.1441E-05" />
    </inertial>

    <visual>
      <origin xyz="0 0 0" rpy="0 0 0" />
      <geometry>
        <mesh filename="package://my_robot/meshes/castor_wheels.STL" scale="1.0 1.0 1.0"/>
      </geometry>
      <material name="black"/>
    </visual>

    <collision>
      <origin xyz="0 0 0" rpy="0 0 0" />
      <geometry>
        <mesh filename="package://my_robot/meshes/castor_wheels.STL" scale="1.0 1.0 1.0"/>
      </geometry>
    </collision>
  </link>

  <joint name="castor_wheels_joint" type="continuous">
    <origin xyz="0.17607 0.003608 -0.079343" rpy="0 0 0" />
    <parent link="base_link" />
    <child link="castor_wheels" />
    <axis xyz="0 1 0" />
    <limit effort="10" velocity="10" />
    <!-- <limit effort="10" velocity="10" /> -->
    <!-- <dynamics damping="0.1" friction="0.0"/> -->
  </joint>

  <gazebo reference = "castor_wheels">
    <material>Gazebo/Black</material>
    <mu1 value = "0.001"/>
    <mu2 value = "0.001"/>
  </gazebo>



  <link name="lidar">
    <inertial>
      <origin xyz="-0.002361 -1.4968E-05 0.019299" rpy="0 0 0" />
      <mass value="0.16538" />
      <inertia
        ixx="7.8866E-05"
        ixy="4.8738E-08"
        ixz="2.1848E-06"
        iyy="7.519E-05"
        iyz="2.8958E-08"
        izz="0.00010995" />
    </inertial>

    <visual>
      <origin xyz="0 0 0" rpy="0 0 0" />
      <geometry>
        <mesh filename="package://my_robot/meshes/lidar.STL" scale="1.0 1.0 1.0"/>
      </geometry>
      <material name="black"/>
    </visual>

    <collision>
      <origin xyz="0 0 0" rpy="0 0 0" />
      <geometry>
        <mesh filename="package://my_robot/meshes/lidar.STL" scale="1.0 1.0 1.0"/>
      </geometry>
    </collision>
  </link>

  <joint name="lidar_joint" type="fixed">
    <origin xyz="0.063868 0.006608 0.050657" rpy="0 0 0" />
    <parent link="base_link" />
    <child link="lidar" />
    <axis xyz="0 0 0" />
  </joint>
  <gazebo reference="lidar">
        <material>Gazebo/Black</material>

        <sensor name="laser" type="ray">
            <pose> 0 0 0 0 0 0 </pose>
            <visualize>true</visualize>
            <update_rate>10</update_rate>
            <ray>
                <scan>
                    <horizontal>
                        <samples>360</samples>
                        <min_angle>-3.14</min_angle>
                        <max_angle>3.14</max_angle>
                    </horizontal>
                </scan>
                <range>
                    <min>0.3</min>
                    <max>12</max>
                </range>
            </ray>
            <plugin name="laser_controller" filename="libgazebo_ros_ray_sensor.so">
                <ros>
                    <argument>~/out:=scan</argument>
                </ros>
                <output_type>sensor_msgs/LaserScan</output_type>
                <frame_name>lidar</frame_name>
            </plugin>
        </sensor>
    </gazebo>



  <link name="camera">
    <inertial>
      <origin xyz="0.0012481 5.1998E-08 0.027201" rpy="0 0 0" />
      <mass value="0.12075" />
      <inertia
        ixx="7.9562E-05"
        ixy="-9.7058E-11"
        ixz="2.8913E-07"
        iyy="3.6327E-05"
        iyz="1.351E-10"
        izz="5.533E-05" />
    </inertial>

    <visual>
      <origin xyz="0 0 0" rpy="0 0 0" />
      <geometry>
        <mesh filename="package://my_robot/meshes/camera.STL" scale="1.0 1.0 1.0"/>
      </geometry>
      <material name="black"/>
    </visual>

    <collision>
      <origin xyz="0 0 0" rpy="0 0 0" />
      <geometry>
        <mesh filename="package://my_robot/meshes/camera.STL" scale="1.0 1.0 1.0"/>
      </geometry>
    </collision>
  </link>

  <joint name="camera_joint" type="fixed">
    <origin xyz="0.12456 0.003608 -0.035343" rpy="0 0 0" />
    <parent link="base_link" />
    <child link="camera" />
    <axis xyz="0 0 0" />
  </joint>
  <gazebo reference="camera">
        <material>Gazebo/Black</material>

        <sensor name="camera" type="camera">
            <pose> 0 0 0 0 0 0 </pose>
            <visualize>true</visualize>
            <update_rate>10</update_rate>
            <camera>
                <horizontal_fov>1.089</horizontal_fov>
                <image>
                    <format>R8G8B8</format>
                    <width>640</width>
                    <height>480</height>
                </image>
                <clip>
                    <near>0.05</near>
                    <far>8.0</far>
                </clip>
            </camera>
            <plugin name="camera_controller" filename="libgazebo_ros_camera.so">
                <frame_name>camera_link_optical</frame_name>
            </plugin>
        </sensor>
    </gazebo>
</robot>

